Workbook

Sheet Product Backlog
C1: Product Backlog - Lista de producto
C2: App móvil Aprueba - Módulo de Preguntas · Grupo 9 · PTY4614 Capstone, sección 002D
C3: Metodología: Extreme Programming · Versión 2.10 · 29 de octubre de 2026
A5: ID | B5: Tipo | C5: Título | D5: Descripción | E5: Criterios de aceptación | F5: Valor para el cliente | G5: Estimación (pts) | H5: Iteración | I5: Estado | J5: Responsable | K5: Objetivo específico | L5: Paquete EDT
A6: E1 | B6: Épica | C6: Plataforma y datos | D6: Habilitadores técnicos que sostienen el resto del producto
A7: F1.1 | B7: Característica | C7: Entorno y despliegue
A8: HT-01 | B8: Historia técnica | C8: Despliegue de la aplicación y de la API | D8: Como equipo de desarrollo, queremos desplegar la aplicación web y la API para que el cliente pueda revisar el avance desde un enlace. | E8: La compilación web y la API responden en Vercel, desde proyectos separados y sin secretos versionados. | F8: Alta | G8: 4 | H8: Iteración 1 | I8: Hecho | J8: Jeremías Fernández | K8: OE2 | L8: 1.3.1.3
A9: T-02 | B9: Tarea | C9: Crear el repositorio y las convenciones de ramas | H9: Iteración 1 | I9: Hecho | J9: Jeremías Fernández
A10: T-03 | B10: Tarea | C10: Desplegar la compilación web en Vercel | H10: Iteración 1 | I10: Hecho | J10: Jeremías Fernández
A11: T-04 | B11: Tarea | C11: Desplegar la API en un proyecto separado de Vercel | H11: Iteración 1 | I11: Hecho | J11: Jeremías Fernández
A12: HT-06 | B12: Historia técnica | C12: Entorno verificado en los tres equipos | D12: Como equipo de desarrollo, queremos que la aplicación funcione en los equipos de los tres integrantes para que todos puedan programar y probar. | E12: La aplicación compila y se ejecuta en los tres equipos siguiendo el README. Se separa de HT-01 en el cierre de la iteración 1. | F12: Alta | G12: 1 | H12: Iteración 5 | I12: Hecho | J12: Equipo completo | K12: OE2 | L12: 1.3.1.1
A13: T-01 | B13: Tarea | C13: Instalar y ejecutar el proyecto en los tres equipos | H13: Iteración 5 | I13: Hecho | J13: Equipo completo
A14: HT-03 | B14: Historia técnica | C14: Contenedores Docker | D14: Como equipo de desarrollo, queremos el proyecto en contenedores para que cualquier persona pueda levantarlo de forma reproducible. | E14: El backend y el emulador de Firestore se levantan con docker-compose, sin secretos versionados, y el procedimiento queda documentado. | F14: Alta | G14: 3 | H14: Iteración 5 | I14: Hecho | J14: Jeremías Fernández | K14: OE4 | L14: 1.3.6.4
A15: T-33 | B15: Tarea | C15: Dockerfile del backend y docker-compose con el emulador de Firestore | H15: Iteración 5 | I15: Hecho | J15: Jeremías Fernández
A16: T-34 | B16: Tarea | C16: Levantar el proyecto con contenedores siguiendo solo la documentación | H16: Iteración 5 | I16: Hecho | J16: Martin Espinoza
A17: F1.2 | B17: Característica | C17: Modelo de datos
A18: HU-20 | B18: Historia técnica | C18: Modelo de datos y modelos de dominio | D18: Como equipo de desarrollo, queremos definir el modelo de datos del módulo y los modelos de dominio del cliente para que las pantallas y los servicios trabajen sobre una misma definición. | E18: Las colecciones, el esquema local y los modelos de dominio están definidos, y sus pruebas unitarias de serialización pasan. | F18: Alta | G18: 5 | H18: Iteración 2 | I18: Hecho | J18: Jeremías Fernández | K18: OE1 | L18: 1.3.2.1 a 1.3.2.3
A19: T-05 | B19: Tarea | C19: Definir las colecciones y las reglas de seguridad de Firestore | H19: Iteración 2 | I19: Hecho | J19: Jeremías Fernández
A20: T-06 | B20: Tarea | C20: Definir los índices compuestos | H20: Iteración 2 | I20: Hecho | J20: Jeremías Fernández
A21: T-07 | B21: Tarea | C21: Revisar el esquema local de Drift | H21: Iteración 2 | I21: Hecho | J21: Sebastián Acevedo
A22: T-08 | B22: Tarea | C22: Implementar los modelos de dominio con pruebas de serialización | H22: Iteración 2 | I22: Hecho | J22: Jeremías / Sebastián
A23: T-09 | B23: Tarea | C23: Cargar el banco de demostración | H23: Iteración 2 | I23: Hecho | J23: Jeremías Fernández
A24: T-10 | B24: Tarea | C24: Alinear recorrecciones, usuarios y medallas con la consola de administración | H24: Iteración 3 | I24: Hecho | J24: Jeremías Fernández
A25: T-42 | B25: Tarea | C25: Corregir el contenido de tres preguntas del banco de demostración (H-12 a H-14) | H25: Iteración 6 | I25: Hecho | J25: Jeremías Fernández
A26: F1.3 | B26: Característica | C26: Backend base
A27: HT-02 | B27: Historia técnica | C27: Backend en FastAPI | D27: Como equipo de desarrollo, queremos el backend en FastAPI con las convenciones de la empresa para que sea consistente con su consola de administración. | E27: La API responde con la estructura común de respuesta y el catálogo de errores, y sus pruebas pasan. | F27: Alta | G27: 5 | H27: Iteración 3 | I27: Hecho | J27: Jeremías Fernández | K27: OE2 | L27: 1.3.1.2
A28: T-11 | B28: Tarea | C28: Migrar la estructura base de Express a FastAPI | H28: Iteración 3 | I28: Hecho | J28: Jeremías Fernández
A29: T-12 | B29: Tarea | C29: Implementar la estructura de respuesta y el catálogo de errores | H29: Iteración 3 | I29: Hecho | J29: Jeremías Fernández
A30: F1.4 | B30: Característica | C30: Calidad e integración | D30: Restricciones técnicas transversales, verificadas en cada iteración mediante los criterios de terminado.
A31: RT-01 | B31: Restricción técnica | C31: Contrato de comunicación común | D31: Los servicios y la aplicación utilizan un contrato de comunicación común. | E31: Los servicios utilizan /api/v1, la estructura de respuesta definida y el catálogo común de errores. | F31: — | G31: — | H31: Iteraciones 2 a 10 | I31: Transversal | J31: Equipo completo | K31: OE2 | L31: Transversal
A32: RT-02 | B32: Restricción técnica | C32: Pruebas y análisis estático | D32: Cada incremento cuenta con pruebas unitarias y análisis estático antes de integrarse. | E32: Las pruebas pasan y el analizador no presenta advertencias antes de considerar terminado un incremento. | F32: — | G32: — | H32: Iteraciones 2 a 10 | I32: Transversal | J32: Equipo completo | K32: OE4 | L32: 1.3.6.1 · 1.3.6.3
A33: RT-03 | B33: Restricción técnica | C33: Integración continua | D33: La aplicación y el backend se integran de forma continua para detectar incompatibilidades temprano. | E33: Los cambios ingresan por solicitud de incorporación revisada por otro integrante y cumplen los contratos establecidos. | F33: — | G33: — | H33: Iteraciones 3 a 10 | I33: Transversal | J33: Equipo completo | K33: OE4 | L33: 1.3.6.2
A34: RT-04 | B34: Restricción técnica | C34: Errores como estados de interfaz | D34: Las restricciones de negocio se presentan al estudiante como estados de interfaz comprensibles. | E34: Los errores de negocio se traducen en estados de interfaz adecuados y no en errores genéricos. | F34: — | G34: — | H34: Iteraciones 3 a 10 | I34: Transversal | J34: Sebastián Acevedo | K34: OE2 | L34: Transversal
A35: T-13 | B35: Tarea | C35: Prueba que verifica que ninguna ruta entregue la alternativa correcta | H35: Iteración 3 | I35: Hecho | J35: Jeremías Fernández
A36: T-24 | B36: Tarea | C36: Diseñar y ejecutar las pruebas de aceptación de la entrega funcional 1 | H36: Iteración 3 | I36: Hecho | J36: Martin Espinoza
A37: T-35 | B37: Tarea | C37: Diseñar y ejecutar las pruebas de aceptación de la iteración 4 | H37: Iteración 4 | I37: Hecho | J37: Martin Espinoza
A38: T-37 | B38: Tarea | C38: Ampliar la prueba de integridad para detectar explanation en todas las rutas | H38: Iteración 4 | I38: Hecho | J38: Jeremías Fernández
A39: T-39 | B39: Tarea | C39: Diseñar y ejecutar las pruebas de aceptación de la iteración 5 | H39: Iteración 5 | I39: Hecho | J39: Martin Espinoza
A40: T-48 | B40: Tarea | C40: Diseñar y ejecutar las pruebas de aceptación de la iteración 6 | H40: Iteración 6 | I40: Hecho | J40: Martin Espinoza
A41: T-51 | B41: Tarea | C41: Alinear con el contrato de la API el estado de la respuesta, los identificadores de habilidades y los errores 405 y 413 | H41: Iteración 6 | I41: Hecho | J41: Jeremías Fernández
...

Sheet Resumen por iteración
A1: Resumen por iteración
A4: Iteración | B4: Historias | C4: Puntos planificados | D4: Puntos terminados | E4: Semana
A5: Iteración 1 | B5: =COUNTIFS('Product Backlog'!$H$6:$H$129,A5,'Product Backlog'!$B$6:$B$129,"Historia*") | C5: =SUMIFS('Product Backlog'!$G$6:$G$129,'Product Backlog'!$H$6:$H$129,A5,'Product Backlog'!$B$6:$B$129,"Historia*") | D5: =SUMIFS('Product Backlog'!$G$6:$G$129,'Product Backlog'!$H$6:$H$129,A5,'Product Backlog'!$B$6:$B$129,"Historia*",'Product Backlog'!$I$6:$I$129,"Hecho") | E5: S5
A6: Iteración 2 | B6: =COUNTIFS('Product Backlog'!$H$6:$H$129,A6,'Product Backlog'!$B$6:$B$129,"Historia*") | C6: =SUMIFS('Product Backlog'!$G$6:$G$129,'Product Backlog'!$H$6:$H$129,A6,'Product Backlog'!$B$6:$B$129,"Historia*") | D6: =SUMIFS('Product Backlog'!$G$6:$G$129,'Product Backlog'!$H$6:$H$129,A6,'Product Backlog'!$B$6:$B$129,"Historia*",'Product Backlog'!$I$6:$I$129,"Hecho") | E6: S6
A7: Iteración 3 | B7: =COUNTIFS('Product Backlog'!$H$6:$H$129,A7,'Product Backlog'!$B$6:$B$129,"Historia*") | C7: =SUMIFS('Product Backlog'!$G$6:$G$129,'Product Backlog'!$H$6:$H$129,A7,'Product Backlog'!$B$6:$B$129,"Historia*") | D7: =SUMIFS('Product Backlog'!$G$6:$G$129,'Product Backlog'!$H$6:$H$129,A7,'Product Backlog'!$B$6:$B$129,"Historia*",'Product Backlog'!$I$6:$I$129,"Hecho") | E7: S7
A8: Iteración 4 | B8: =COUNTIFS('Product Backlog'!$H$6:$H$129,A8,'Product Backlog'!$B$6:$B$129,"Historia*") | C8: =SUMIFS('Product Backlog'!$G$6:$G$129,'Product Backlog'!$H$6:$H$129,A8,'Product Backlog'!$B$6:$B$129,"Historia*") | D8: =SUMIFS('Product Backlog'!$G$6:$G$129,'Product Backlog'!$H$6:$H$129,A8,'Product Backlog'!$B$6:$B$129,"Historia*",'Product Backlog'!$I$6:$I$129,"Hecho") | E8: S8
A9: Iteración 5 | B9: =COUNTIFS('Product Backlog'!$H$6:$H$129,A9,'Product Backlog'!$B$6:$B$129,"Historia*") | C9: =SUMIFS('Product Backlog'!$G$6:$G$129,'Product Backlog'!$H$6:$H$129,A9,'Product Backlog'!$B$6:$B$129,"Historia*") | D9: =SUMIFS('Product Backlog'!$G$6:$G$129,'Product Backlog'!$H$6:$H$129,A9,'Product Backlog'!$B$6:$B$129,"Historia*",'Product Backlog'!$I$6:$I$129,"Hecho") | E9: S9
A10: Iteración 6 | B10: =COUNTIFS('Product Backlog'!$H$6:$H$129,A10,'Product Backlog'!$B$6:$B$129,"Historia*") | C10: =SUMIFS('Product Backlog'!$G$6:$G$129,'Product Backlog'!$H$6:$H$129,A10,'Product Backlog'!$B$6:$B$129,"Historia*") | D10: =SUMIFS('Product Backlog'!$G$6:$G$129,'Product Backlog'!$H$6:$H$129,A10,'Product Backlog'!$B$6:$B$129,"Historia*",'Product Backlog'!$I$6:$I$129,"Hecho") | E10: S10
A11: Iteración 7 | B11: =COUNTIFS('Product Backlog'!$H$6:$H$129,A11,'Product Backlog'!$B$6:$B$129,"Historia*") | C11: =SUMIFS('Product Backlog'!$G$6:$G$129,'Product Backlog'!$H$6:$H$129,A11,'Product Backlog'!$B$6:$B$129,"Historia*") | D11: =SUMIFS('Product Backlog'!$G$6:$G$129,'Product Backlog'!$H$6:$H$129,A11,'Product Backlog'!$B$6:$B$129,"Historia*",'Product Backlog'!$I$6:$I$129,"Hecho") | E11: S11
A12: Iteración 8 | B12: =COUNTIFS('Product Backlog'!$H$6:$H$129,A12,'Product Backlog'!$B$6:$B$129,"Historia*") | C12: =SUMIFS('Product Backlog'!$G$6:$G$129,'Product Backlog'!$H$6:$H$129,A12,'Product Backlog'!$B$6:$B$129,"Historia*") | D12: =SUMIFS('Product Backlog'!$G$6:$G$129,'Product Backlog'!$H$6:$H$129,A12,'Product Backlog'!$B$6:$B$129,"Historia*",'Product Backlog'!$I$6:$I$129,"Hecho") | E12: S12
A13: Iteración 9 | B13: =COUNTIFS('Product Backlog'!$H$6:$H$129,A13,'Product Backlog'!$B$6:$B$129,"Historia*") | C13: =SUMIFS('Product Backlog'!$G$6:$G$129,'Product Backlog'!$H$6:$H$129,A13,'Product Backlog'!$B$6:$B$129,"Historia*") | D13: =SUMIFS('Product Backlog'!$G$6:$G$129,'Product Backlog'!$H$6:$H$129,A13,'Product Backlog'!$B$6:$B$129,"Historia*",'Product Backlog'!$I$6:$I$129,"Hecho") | E13: S13
A14: Iteración 10 | B14: =COUNTIFS('Product Backlog'!$H$6:$H$129,A14,'Product Backlog'!$B$6:$B$129,"Historia*") | C14: =SUMIFS('Product Backlog'!$G$6:$G$129,'Product Backlog'!$H$6:$H$129,A14,'Product Backlog'!$B$6:$B$129,"Historia*") | D14: =SUMIFS('Product Backlog'!$G$6:$G$129,'Product Backlog'!$H$6:$H$129,A14,'Product Backlog'!$B$6:$B$129,"Historia*",'Product Backlog'!$I$6:$I$129,"Hecho") | E14: S14
A15: Total | B15: =SUM(B5:B14) | C15: =SUM(C5:C14) | D15: =SUM(D5:D14)

Sheet Conteo
A1: Conteo por tipo y estado
A2: Se calcula con fórmulas sobre la hoja Product Backlog; se actualiza solo al cambiar los estados.
A4: Tipo | B4: Total | C4: Hechas | D4: Pendientes | E4: Otros estados | F4: Puntos | G4: Puntos terminados
A5: Épicas | B5: =COUNTIF('Product Backlog'!$B$6:$B$129,"Épica") | C5: — | D5: — | E5: — | F5: — | G5: —
A6: Características | B6: =COUNTIF('Product Backlog'!$B$6:$B$129,"Característica") | C6: — | D6: — | E6: — | F6: — | G6: —
A7: Historias de usuario | B7: =COUNTIF('Product Backlog'!$B$6:$B$129,"Historia de usuario") | C7: =COUNTIFS('Product Backlog'!$B$6:$B$129,"Historia de usuario",'Product Backlog'!$I$6:$I$129,"Hecho") | D7: =COUNTIFS('Product Backlog'!$B$6:$B$129,"Historia de usuario",'Product Backlog'!$I$6:$I$129,"Pendiente") | E7: =B7-C7-D7 | F7: =SUMIFS('Product Backlog'!$G$6:$G$129,'Product Backlog'!$B$6:$B$129,"Historia de usuario") | G7: =SUMIFS('Product Backlog'!$G$6:$G$129,'Product Backlog'!$B$6:$B$129,"Historia de usuario",'Product Backlog'!$I$6:$I$129,"Hecho")
A8: Historias técnicas | B8: =COUNTIF('Product Backlog'!$B$6:$B$129,"Historia técnica") | C8: =COUNTIFS('Product Backlog'!$B$6:$B$129,"Historia técnica",'Product Backlog'!$I$6:$I$129,"Hecho") | D8: =COUNTIFS('Product Backlog'!$B$6:$B$129,"Historia técnica",'Product Backlog'!$I$6:$I$129,"Pendiente") | E8: =B8-C8-D8 | F8: =SUMIFS('Product Backlog'!$G$6:$G$129,'Product Backlog'!$B$6:$B$129,"Historia técnica") | G8: =SUMIFS('Product Backlog'!$G$6:$G$129,'Product Backlog'!$B$6:$B$129,"Historia técnica",'Product Backlog'!$I$6:$I$129,"Hecho")
A9: Restricciones técnicas | B9: =COUNTIF('Product Backlog'!$B$6:$B$129,"Restricción técnica") | C9: =COUNTIFS('Product Backlog'!$B$6:$B$129,"Restricción técnica",'Product Backlog'!$I$6:$I$129,"Hecho") | D9: =COUNTIFS('Product Backlog'!$B$6:$B$129,"Restricción técnica",'Product Backlog'!$I$6:$I$129,"Pendiente") | E9: =B9-C9-D9 | F9: — | G9: —
A10: Tareas | B10: =COUNTIF('Product Backlog'!$B$6:$B$129,"Tarea") | C10: =COUNTIFS('Product Backlog'!$B$6:$B$129,"Tarea",'Product Backlog'!$I$6:$I$129,"Hecho") | D10: =COUNTIFS('Product Backlog'!$B$6:$B$129,"Tarea",'Product Backlog'!$I$6:$I$129,"Pendiente") | E10: =B10-C10-D10 | F10: — | G10: —
A11: Historias (de usuario y técnicas) | B11: =B7+B8 | C11: =C7+C8 | D11: =D7+D8 | E11: =E7+E8 | F11: =F7+F8 | G11: =G7+G8
A13: Otros estados: Transversal (restricciones técnicas).
A15: Tareas por iteración
A16: Iteración | B16: Tareas | C16: Hechas | D16: Pendientes | E16: Otros estados
A17: Iteración 1 | B17: =COUNTIFS('Product Backlog'!$B$6:$B$129,"Tarea",'Product Backlog'!$H$6:$H$129,A17) | C17: =COUNTIFS('Product Backlog'!$B$6:$B$129,"Tarea",'Product Backlog'!$H$6:$H$129,A17,'Product Backlog'!$I$6:$I$129,"Hecho") | D17: =COUNTIFS('Product Backlog'!$B$6:$B$129,"Tarea",'Product Backlog'!$H$6:$H$129,A17,'Product Backlog'!$I$6:$I$129,"Pendiente") | E17: =B17-C17-D17
A18: Iteración 2 | B18: =COUNTIFS('Product Backlog'!$B$6:$B$129,"Tarea",'Product Backlog'!$H$6:$H$129,A18) | C18: =COUNTIFS('Product Backlog'!$B$6:$B$129,"Tarea",'Product Backlog'!$H$6:$H$129,A18,'Product Backlog'!$I$6:$I$129,"Hecho") | D18: =COUNTIFS('Product Backlog'!$B$6:$B$129,"Tarea",'Product Backlog'!$H$6:$H$129,A18,'Product Backlog'!$I$6:$I$129,"Pendiente") | E18: =B18-C18-D18
A19: Iteración 3 | B19: =COUNTIFS('Product Backlog'!$B$6:$B$129,"Tarea",'Product Backlog'!$H$6:$H$129,A19) | C19: =COUNTIFS('Product Backlog'!$B$6:$B$129,"Tarea",'Product Backlog'!$H$6:$H$129,A19,'Product Backlog'!$I$6:$I$129,"Hecho") | D19: =COUNTIFS('Product Backlog'!$B$6:$B$129,"Tarea",'Product Backlog'!$H$6:$H$129,A19,'Product Backlog'!$I$6:$I$129,"Pendiente") | E19: =B19-C19-D19
A20: Iteración 4 | B20: =COUNTIFS('Product Backlog'!$B$6:$B$129,"Tarea",'Product Backlog'!$H$6:$H$129,A20) | C20: =COUNTIFS('Product Backlog'!$B$6:$B$129,"Tarea",'Product Backlog'!$H$6:$H$129,A20,'Product Backlog'!$I$6:$I$129,"Hecho") | D20: =COUNTIFS('Product Backlog'!$B$6:$B$129,"Tarea",'Product Backlog'!$H$6:$H$129,A20,'Product Backlog'!$I$6:$I$129,"Pendiente") | E20: =B20-C20-D20
A21: Iteración 5 | B21: =COUNTIFS('Product Backlog'!$B$6:$B$129,"Tarea",'Product Backlog'!$H$6:$H$129,A21) | C21: =COUNTIFS('Product Backlog'!$B$6:$B$129,"Tarea",'Product Backlog'!$H$6:$H$129,A21,'Product Backlog'!$I$6:$I$129,"Hecho") | D21: =COUNTIFS('Product Backlog'!$B$6:$B$129,"Tarea",'Product Backlog'!$H$6:$H$129,A21,'Product Backlog'!$I$6:$I$129,"Pendiente") | E21: =B21-C21-D21
A22: Iteración 6 | B22: =COUNTIFS('Product Backlog'!$B$6:$B$129,"Tarea",'Product Backlog'!$H$6:$H$129,A22) | C22: =COUNTIFS('Product Backlog'!$B$6:$B$129,"Tarea",'Product Backlog'!$H$6:$H$129,A22,'Product Backlog'!$I$6:$I$129,"Hecho") | D22: =COUNTIFS('Product Backlog'!$B$6:$B$129,"Tarea",'Product Backlog'!$H$6:$H$129,A22,'Product Backlog'!$I$6:$I$129,"Pendiente") | E22: =B22-C22-D22
A23: Iteración 7 | B23: =COUNTIFS('Product Backlog'!$B$6:$B$129,"Tarea",'Product Backlog'!$H$6:$H$129,A23) | C23: =COUNTIFS('Product Backlog'!$B$6:$B$129,"Tarea",'Product Backlog'!$H$6:$H$129,A23,'Product Backlog'!$I$6:$I$129,"Hecho") | D23: =COUNTIFS('Product Backlog'!$B$6:$B$129,"Tarea",'Product Backlog'!$H$6:$H$129,A23,'Product Backlog'!$I$6:$I$129,"Pendiente") | E23: =B23-C23-D23
A24: Iteración 8 | B24: =COUNTIFS('Product Backlog'!$B$6:$B$129,"Tarea",'Product Backlog'!$H$6:$H$129,A24) | C24: =COUNTIFS('Product Backlog'!$B$6:$B$129,"Tarea",'Product Backlog'!$H$6:$H$129,A24,'Product Backlog'!$I$6:$I$129,"Hecho") | D24: =COUNTIFS('Product Backlog'!$B$6:$B$129,"Tarea",'Product Backlog'!$H$6:$H$129,A24,'Product Backlog'!$I$6:$I$129,"Pendiente") | E24: =B24-C24-D24
A25: Iteración 9 | B25: =COUNTIFS('Product Backlog'!$B$6:$B$129,"Tarea",'Product Backlog'!$H$6:$H$129,A25) | C25: =COUNTIFS('Product Backlog'!$B$6:$B$129,"Tarea",'Product Backlog'!$H$6:$H$129,A25,'Product Backlog'!$I$6:$I$129,"Hecho") | D25: =COUNTIFS('Product Backlog'!$B$6:$B$129,"Tarea",'Product Backlog'!$H$6:$H$129,A25,'Product Backlog'!$I$6:$I$129,"Pendiente") | E25: =B25-C25-D25
A26: Iteración 10 | B26: =COUNTIFS('Product Backlog'!$B$6:$B$129,"Tarea",'Product Backlog'!$H$6:$H$129,A26) | C26: =COUNTIFS('Product Backlog'!$B$6:$B$129,"Tarea",'Product Backlog'!$H$6:$H$129,A26,'Product Backlog'!$I$6:$I$129,"Hecho") | D26: =COUNTIFS('Product Backlog'!$B$6:$B$129,"Tarea",'Product Backlog'!$H$6:$H$129,A26,'Product Backlog'!$I$6:$I$129,"Pendiente") | E26: =B26-C26-D26
A27: Por planificar | B27: =COUNTIFS('Product Backlog'!$B$6:$B$129,"Tarea",'Product Backlog'!$H$6:$H$129,A27) | C27: =COUNTIFS('Product Backlog'!$B$6:$B$129,"Tarea",'Product Backlog'!$H$6:$H$129,A27,'Product Backlog'!$I$6:$I$129,"Hecho") | D27: =COUNTIFS('Product Backlog'!$B$6:$B$129,"Tarea",'Product Backlog'!$H$6:$H$129,A27,'Product Backlog'!$I$6:$I$129,"Pendiente") | E27: =B27-C27-D27
A28: Total | B28: =SUM(B17:B27) | C28: =SUM(C17:C27) | D28: =SUM(D17:D27) | E28: =SUM(E17:E27)

Sheet Tareas
A1: Tareas por número
A2: Todas las tareas del Product Backlog en orden de número, con la historia a la que pertenecen. Las pruebas de aceptación y las tareas de calidad pertenecen a la característica F1.4 (Calidad e integración).
A4: ID | B4: Tarea | C4: Historia | D4: Iteración | E4: Estado | F4: Responsable
A5: T-01 | B5: Instalar y ejecutar el proyecto en los tres equipos | C5: HT-06 | D5: Iteración 5 | E5: Hecho | F5: Equipo completo
A6: T-02 | B6: Crear el repositorio y las convenciones de ramas | C6: HT-01 | D6: Iteración 1 | E6: Hecho | F6: Jeremías Fernández
A7: T-03 | B7: Desplegar la compilación web en Vercel | C7: HT-01 | D7: Iteración 1 | E7: Hecho | F7: Jeremías Fernández
A8: T-04 | B8: Desplegar la API en un proyecto separado de Vercel | C8: HT-01 | D8: Iteración 1 | E8: Hecho | F8: Jeremías Fernández
A9: T-05 | B9: Definir las colecciones y las reglas de seguridad de Firestore | C9: HU-20 | D9: Iteración 2 | E9: Hecho | F9: Jeremías Fernández
A10: T-06 | B10: Definir los índices compuestos | C10: HU-20 | D10: Iteración 2 | E10: Hecho | F10: Jeremías Fernández
A11: T-07 | B11: Revisar el esquema local de Drift | C11: HU-20 | D11: Iteración 2 | E11: Hecho | F11: Sebastián Acevedo
A12: T-08 | B12: Implementar los modelos de dominio con pruebas de serialización | C12: HU-20 | D12: Iteración 2 | E12: Hecho | F12: Jeremías / Sebastián
A13: T-09 | B13: Cargar el banco de demostración | C13: HU-20 | D13: Iteración 2 | E13: Hecho | F13: Jeremías Fernández
A14: T-10 | B14: Alinear recorrecciones, usuarios y medallas con la consola de administración | C14: HU-20 | D14: Iteración 3 | E14: Hecho | F14: Jeremías Fernández
A15: T-11 | B15: Migrar la estructura base de Express a FastAPI | C15: HT-02 | D15: Iteración 3 | E15: Hecho | F15: Jeremías Fernández
... A78: T-74 | B78: Mostrar el enunciado de la pregunta en lugar de los identificadores internos en la recorrección (H-35) | C78: HU-09 | D78: Por planificar | E78: Pendiente | F78: Sebastián Acevedo

Sheet Notas
A1: Notas del Product Backlog
A3: Estructura
A4: El Product Backlog es la lista completa del producto. Se organiza en cuatro niveles: épicas, que agrupan grandes capacidades; características, que dividen cada épica; historias de usuario, que describen el valor para el estudiante; y tareas, que detallan el trabajo técnico de cada historia.
A6: Historias técnicas y restricciones
A7: Las historias técnicas describen habilitadores que no entregan valor directo al estudiante, pero son necesarios para el producto. Las restricciones técnicas no son historias: atraviesan todo el desarrollo y se verifican en cada iteración mediante los criterios de terminado.
A9: Priorización
A10: En Extreme Programming el cliente prioriza por valor y el equipo estima el costo. No se utiliza MoSCoW porque todas las historias corresponden a alcance comprometido.
A12: Estimación
A13: Estimación inicial en puntos de historia, escala 1, 2, 3, 5 y 8. Se ajusta en el juego de planificación al inicio de cada iteración.
A15: Tareas
A16: Las tareas se detallan al inicio de cada iteración en su plan de iteración y se registran también en este Product Backlog, bajo la historia a la que pertenecen. Las tareas que nacen de un hallazgo quedan por planificar hasta que el juego de planificación les asigna una iteración.
A18: Cambios de la versión 2.10
... A52: Se reorganizó la lista en épicas, características, historias y tareas. Se agregaron la historia HU-21 de inicio de sesión, autorizada por el cliente y las historias técnicas HT-01 a HT-05. Se actualizaron HU-01, HU-03, HU-07, HU-08, HU-09, HU-14 y HU-16 según las definiciones del cliente: backend en FastAPI, autenticación con Firebase, versión web como plataforma y compatibilidad con la consola de administración.
